<?xml version="1.0" encoding="utf-8"?>
<!-- This URDF was automatically created by SolidWorks to URDF Exporter! Originally created by Stephen Brawner (brawner@gmail.com) 
     Commit Version: 1.6.0-1-g15f4949  Build Version: 1.6.7594.29634
     For more information, please see http://wiki.ros.org/sw_urdf_exporter -->


<robot name="hunter2" xmlns:xacro="http://www.ros.org/wiki/xacro">

<xacro:include filename="$(find hunter2_gazebo)/xacro/hunter2.gazebo"/>
<xacro:include filename="$(find hunter2_gazebo)/xacro/hunter2sensor.gazebo"/>

  <link name="base_footprint">
  </link>
  
  <joint name="base_footprint_to_base_link" type="fixed">
    <origin xyz="0 0 0.33158" rpy="0 0 0" />
    <parent link="base_footprint" />
    <child link="base_link" />
  </joint>

  <link name="base_link">
    <inertial>
      <origin
        xyz="0.0266989327622036 0.000409203500587652 -0.135901124750884"
        rpy="0 0 0" />
      <mass
        value="10" />
      <inertia
        ixx="0.0332370959804736"
        ixy="-1.013150489971E-06"
        ixz="-0.00188859201421112"
        iyy="0.111072002332437"
        iyz="-5.13308150598312E-07"
        izz="0.12660862809283" />
    </inertial>
    <visual>
      <origin
        xyz="0 0 0"
        rpy="0 0 0" />
      <geometry>
        <mesh
          filename="file://$(find hunter2_base)/meshes/base_link.STL" />
      </geometry>
      <material
        name="offwhite">
      </material>
    </visual>
    <collision>
      <origin
        xyz="0 0 0"
        rpy="0 0 0" />
      <geometry>
        <mesh
          filename="file://$(find hunter2_base)/meshes/base_link.STL" />
      </geometry>
    </collision>
  </link>

  <link
    name="front_steer_left_link">
    <inertial>
      <origin
        xyz="-0.012614 1.8116E-05 0.0023132"
        rpy="0 0 0" />
      <mass
        value="0.5" />
      <inertia
        ixx="0.0222"
        ixy="0.0"
        ixz="0.0"
        iyy="0.0222"
        iyz="0.0"
        izz="0.0378075" />
    </inertial>
    <visual>
      <origin
        xyz="0 0 0"
        rpy="0 0 0" />
      <geometry>
        <box size="0.001 0.001 0.001"/>
      </geometry>
      <material
        name="mediumgrey">
      </material>
    </visual>
    <collision>
      <origin
        xyz="0 0 0"
        rpy="0 0 0" />
      <geometry>
        <box size="0.001 0.001 0.001"/>
      </geometry>
    </collision>
  </link>
  <joint
    name="front_steer_left_joint"
    type="continuous">
    <origin
      xyz="0.37142 0.29199 -0.1955"
      rpy="1.5708 0 0" />
    <parent
      link="base_link" />
    <child
      link="front_steer_left_link" />
    <axis
      xyz="0 1 0" />
    <limit
      lower="-0.69"
      upper="0.69"
      effort="10"
      velocity="0.69" />
  </joint>
  <link
    name="front_left_wheel_link">
    <inertial>
      <origin
        xyz="-6.5774E-06 2.0242E-05 -0.0096386"
        rpy="0 0 0" />
      <mass
        value="1" />
      <inertia
        ixx="0.063724"
        ixy="0"
        ixz="0"
        iyy="0.063724"
        iyz="0"
        izz="0.11072" />
    </inertial>
    <visual>
      <origin
        xyz="0 0 0"
        rpy="0 0 0" />
      <geometry>
        <mesh
          filename="file://$(find hunter2_base)/meshes/front_left_wheel_link.STL" />
      </geometry>
      <material
        name="battleshipgrey">
      </material>
    </visual>
    <collision>
      <origin
        xyz="0 0 0"
        rpy="0 0 0" />
      <geometry>
        <cylinder radius="0.165" length="0.14"/>
      </geometry>
    </collision>
  </link>
  <joint
    name="front_left_wheel_joint"
    type="continuous">
    <origin
      xyz="0 0 0"
      rpy="0 0 0" />
    <parent
      link="front_steer_left_link" />
    <child
      link="front_left_wheel_link" />
    <axis
      xyz="0 0 -1" />
    <limit effort="10" velocity="100" />

  </joint>
  <link
    name="front_steer_right_link">
    <inertial>
      <origin
        xyz="-8.9374E-08 1.0997E-07 0.0095958"
        rpy="0 0 0" />
      <mass
        value="0.5" />
      <inertia
        ixx="0.0222"
        ixy="0.0"
        ixz="0.0"
        iyy="0.0222"
        iyz="0.0"
        izz="0.0378075" />
    </inertial>
    <visual>
      <origin
        xyz="0 0 0"
        rpy="0 0 0" />
      <geometry>
        <box size="0.001 0.001 0.001"/>
      </geometry>
      <material
        name="battleshipgrey">
      </material>
    </visual>
    <collision>
      <origin
        xyz="0 0 0"
        rpy="0 0 0" />
      <geometry>
        <box size="0.001 0.001 0.001"/>
      </geometry>
    </collision>
  </link>
  <joint
    name="front_steer_right_joint"
    type="continuous">
    <origin
      xyz="0.37142 -0.29201 -0.1955"
      rpy="1.5708 0 0" />
    <parent
      link="base_link" />
    <child
      link="front_steer_right_link" />
    <axis
      xyz="0 1 0" />
    <limit
      lower="-0.69"
      upper="0.69"
      effort="10"
      velocity="0.69" />
  </joint>
  <link
    name="front_right_wheel_link">
    <inertial>
      <origin
        xyz="-9.1148E-08 1.1284E-07 0.0095049"
        rpy="0 0 0" />
      <mass
        value="1" />
      <inertia
        ixx="0.063626"
        ixy="0"
        ixz="0"
        iyy="0.063626"
        iyz="0"
        izz="0.11054" />
    </inertial>
    <visual>
      <origin
        xyz="0 0 0"
        rpy="0 3.14 0" />
      <geometry>
        <mesh
          filename="file://$(find hunter2_base)/meshes/front_left_wheel_link.STL" />
      </geometry>
      <material
        name="battleshipgrey">
      </material>
    </visual>
    <collision>
      <origin
        xyz="0 0 0"
        rpy="0 0 0" />
      <geometry>
        <cylinder radius="0.165" length="0.14"/>

      </geometry>
    </collision>
  </link>
  <joint
    name="front_right_wheel_joint"
    type="continuous">
    <origin
      xyz="0 0 0"
      rpy="0 0 0" />
    <parent
      link="front_steer_right_link" />
    <child
      link="front_right_wheel_link" />
    <axis
      xyz="0 0 -1" />
    <limit effort="10" velocity="100" />

  </joint>
  <link
    name="rear_left_link">
    <inertial>
      <origin
        xyz="-8.826E-05 6.4342E-05 -0.0096491"
        rpy="0 0 0" />
      <mass
        value="1" />
      <inertia
        ixx="0.063699"
        ixy="0"
        ixz="0"
        iyy="0.063699"
        iyz="0"
        izz="0.11067" />
    </inertial>
    <visual>
      <origin
        xyz="0 0 0"
        rpy="0 0 0" />
      <geometry>
        <mesh
          filename="file://$(find hunter2_base)/meshes/left_rear_link.STL" />
      </geometry>
      <material
        name="battleshipgrey">
      </material>
    </visual>
    <collision>
      <origin
        xyz="0 0 0"
        rpy="0 0 0" />
      <geometry>
        <cylinder radius="0.165" length="0.14"/>

      </geometry>
    </collision>
  </link>
  <joint
    name="rear_left_joint"
    type="continuous">
    <origin
      xyz="-0.28 0.29249 -0.19558"
      rpy="1.5708 0 0" />
    <parent
      link="base_link" />
    <child
      link="rear_left_link" />
    <axis
      xyz="0 0 -1" />
    <limit effort="10" velocity="100" />

  </joint>
  <link
    name="rear_right_link">
    <inertial>
      <origin
        xyz="8.6344E-05 7.4488E-05 0.0097824"
        rpy="0 0 0" />
      <mass
        value="1" />
      <inertia
        ixx="0.06373"
        ixy="0"
        ixz="0"
        iyy="0.06373"
        iyz="0"
        izz="0.11073" />
    </inertial>
    <visual>
      <origin
        xyz="0 0 0"
        rpy="0 0 0" />
      <geometry>
        <mesh
          filename="file://$(find hunter2_base)/meshes/right_rear_link.STL" />
      </geometry>
      <material
        name="battleshipgrey">
      </material>
    </visual>
    <collision>
      <origin
        xyz="0 0 0"
        rpy="0 0 0" />
      <geometry>
         <cylinder radius="0.165" length="0.14"/>

      </geometry>
    </collision>
  </link>
  <joint
    name="rear_right_joint"
    type="continuous">
    <origin
      xyz="-0.28018 -0.29251 -0.19558"
      rpy="1.5708 0.0026575 0" />
    <parent
      link="base_link" />
    <child
      link="rear_right_link" />
    <axis
      xyz="0 0 -1" />
    <limit effort="10" velocity="100" />

  </joint>
  <link
    name="front_steer_link">
    <inertial>
      <origin
        xyz="0.049836 8.1046E-15 0.017912"
        rpy="0 0 0" />
      <mass
        value="0.049179" />
      <inertia
        ixx="1.6846E-07"
        ixy="7.6396E-23"
        ixz="-1.0974E-08"
        iyy="7.549E-07"
        iyz="-1.8957E-22"
        izz="7.334E-07" />
    </inertial>
    <visual>
      <origin
        xyz="0 0 0"
        rpy="0 0 0" />
      <geometry>
      <cylinder length="0.001" radius="0.005"/>
      </geometry>
      <material
        name="">
        <color
          rgba="0.79216 0.81961 0.93333 1" />
      </material>
    </visual>
    <collision>
      <origin
        xyz="0 0 0"
        rpy="0 0 0" />
      <geometry>
      <cylinder length="0.001" radius="0.005"/>
      </geometry>
    </collision>
  </link>
  <joint
    name="front_steer_joint"
    type="continuous">
    <origin
      xyz="0.44792 -1.1431E-05 -0.121"
      rpy="0 0 0" />
    <parent
      link="base_link" />
    <child
      link="front_steer_link" />
    <axis
      xyz="0 0 1" />
    <limit
      lower="-0.72"
      upper="0.72"
      effort="10"
      velocity="100" />
  </joint>
  <link
    name="rear_wheel_link">
<inertial>
      <origin
        xyz="-0.02 0.0031269 -0.12735"
        rpy="0 0 0" />
      <mass
        value="0.049179" />
      <inertia
        ixx="1.1821E-06"
        ixy="9.6965E-13"
        ixz="-3.1553E-12"
        iyy="9.5276E-07"
        iyz="1.2428E-08"
        izz="1.0913E-06" />
    </inertial>
    <visual>
      <origin
        xyz="0 0 0"
        rpy="0 0 0" />
      <geometry>
      <cylinder length="0.001" radius="0.005"/>
      </geometry>
      <material
        name="">
        <color
          rgba="1 1 1 1" />
      </material>
    </visual>
    <collision>
      <origin
        xyz="0 0 0"
        rpy="0 0 0" />
      <geometry>
      <cylinder length="0.001" radius="0.005"/>
      </geometry>
    </collision>
  </link>
  <joint
    name="rear_wheel_joint"
    type="fixed">
    <origin
      xyz="-0.42408 -1.1431E-05 -0.085581"
      rpy="0.0032313 0 0" />
    <parent
      link="base_link" />
    <child
      link="rear_wheel_link" />
    <axis
      xyz="0 0 1" />
  </joint>
  
<xacro:macro name="wheel_transmission" params="name">
  <transmission name="${name}_transmission" type="SimpleTransmission">
    <type>transmission_interface/SimpleTransmission</type>
    <joint name="${name}_joint">
      <hardwareInterface>EffortJointInterface</hardwareInterface>
    </joint>
    <actuator name="${name}_motor">
      <hardwareInterface>EffortJointInterface</hardwareInterface>
      <mechanicalReduction>1</mechanicalReduction>
    </actuator>
  </transmission>
</xacro:macro>

<xacro:macro name="steering_hinge_transmission" params="name">
  <transmission name="${name}_transmission" type="SimpleTransmission">
    <type>transmission_interface/SimpleTransmission</type>
    <joint name="${name}_joint">
      <hardwareInterface>EffortJointInterface</hardwareInterface>
    </joint>
    <actuator name="${name}_motor">
      <hardwareInterface>EffortJointInterface</hardwareInterface>
      <mechanicalReduction>1</mechanicalReduction>
    </actuator>
  </transmission>
</xacro:macro>


  <xacro:steering_hinge_transmission name="front_steer_left" />
  <xacro:steering_hinge_transmission name="front_steer_right" />
  <xacro:steering_hinge_transmission name="front_steer" />

  <xacro:wheel_transmission name="front_left_wheel" />
  <xacro:wheel_transmission name="front_right_wheel" />
  <xacro:wheel_transmission name="rear_left" />
  <xacro:wheel_transmission name="rear_right" />

  <!-- ================== IMU ================== -->
  <link name="imu_link">
    <inertial>
      <mass value="0.05"/>
      <origin xyz="0 0 0" rpy="0 0 0"/>
      <inertia ixx="1e-6" iyy="1e-6" izz="1e-6" ixy="0" ixz="0" iyz="0"/>
    </inertial>
    <visual>
      <origin xyz="0 0 0" rpy="0 0 0"/>
      <geometry><box size="0.02 0.02 0.02"/></geometry>
      <material name="imu_green"><color rgba="0.2 0.8 0.2 1.0"/></material>
    </visual>
  </link>

  <joint name="imu_joint" type="fixed">
    <parent link="base_link"/>
    <!-- posicione a IMU no chassis -->
    <child link="imu_link"/>
    <origin xyz="0 0 0.1" rpy="0 0 0"/>
  </joint>

  <!-- ================== LiDAR 3D ================== -->
<link name="lidar_link">
  <inertial>
    <mass value="0.3"/>
    <origin xyz="0 0 0" rpy="0 0 0"/>
    <inertia ixx="1e-4" iyy="1e-4" izz="1e-4" ixy="0" ixz="0" iyz="0"/>
  </inertial>
  <visual>
    <origin xyz="0 0 0" rpy="0 0 0"/>
    <geometry><cylinder radius="0.05" length="0.06"/></geometry>
    <material name="lidar_black"><color rgba="0.1 0.1 0.1 1.0"/></material>
  </visual>
</link>

  <!-- ================== LiDAR 2D ================== -->

<joint name="lidar_2d_joint" type="fixed">
  <parent link="base_link"/>
  <child link="lidar_2d_link"/>
  <origin xyz="0.55 0 -0.10" rpy="0 0 0"/>
</joint>

<link name="lidar_2d_link">
  <inertial>
    <mass value="0.3"/>
    <origin xyz="0 0 0" rpy="0 0 0"/>
    <inertia ixx="1e-4" iyy="1e-4" izz="1e-4" ixy="0" ixz="0" iyz="0"/>
  </inertial>
  <visual>
    <origin xyz="0 0 0" rpy="0 0 0"/>
    <geometry><cylinder radius="0.05" length="0.06"/></geometry>
    <material name="lidar_black"><color rgba="0.1 0.1 0.1 1.0"/></material>
  </visual>
</link>

<joint name="lidar_joint" type="fixed">
  <parent link="base_link"/>
  <!-- coloque o LiDAR no “teto”/frente -->
  <child link="lidar_link"/>
  <origin xyz="0.0 0 0.35" rpy="0 0 0"/>
</joint>

<ros2_control name="GazeboSimSystem" type="system">
  <hardware>
    <plugin>gz_ros2_control/GazeboSimSystem</plugin>
  </hardware>

  <!-- Rodas dianteiras (vamos expor comando em VELOCIDADE) -->
  <joint name="front_left_wheel_joint">
 
      <state_interface name="position"/>
      <state_interface name="velocity"/>
  </joint>

  <joint name="front_right_wheel_joint">

 
      <state_interface name="position"/>
      <state_interface name="velocity"/>

  </joint>

  <!-- Rodas traseiras -->
  <joint name="rear_left_joint">

 
      <state_interface name="position"/>
      <state_interface name="velocity"/>

  </joint>

  <joint name="rear_right_joint">

 
      <state_interface name="position"/>
      <state_interface name="velocity"/>

  </joint>

  <!-- Esterço (faz sentido “position” como comando) -->
  <joint name="front_steer_left_joint">


      <state_interface name="position"/>
      <state_interface name="velocity"/>

  </joint>

  <joint name="front_steer_right_joint">


      <state_interface name="position"/>
      <state_interface name="velocity"/>

  </joint>
</ros2_control>
</robot>
